<?xml version="1.0" encoding="utf-8"?>
<!-- This URDF was automatically created by SolidWorks to URDF Exporter! Originally created by Stephen Brawner (brawner@gmail.com) 
     Commit Version: 1.6.0-4-g7f85cfe  Build Version: 1.6.7995.38578
     For more information, please see http://wiki.ros.org/sw_urdf_exporter -->
<robot
  name="rover_base" xmlns:xacro="http://www.ros.org/wiki/xacro">

  <!--TODO: will be updated as 0.326249999857664 + wheel radius -->
  <xacro:property name="base_height" value="0.526249999857664" />

  <link name="base_footprint" />


  <link
    name="base_link">
    <inertial>
      <origin
        xyz="0.0724922097398836 -0.000610314099648894 -0.169101282367528"
        rpy="0 0 0" />
      <mass
        value="3.48464795879982" />
      <inertia
        ixx="0.0500944839069271"
        ixy="1.53786219976395E-05"
        ixz="9.75857699924731E-06"
        iyy="0.0167322893525171"
        iyz="5.6805400994026E-08"
        izz="0.0592559269432614" />
    </inertial>
    <visual>
      <origin
        xyz="0 0 0"
        rpy="0 0 0" />
      <geometry>
        <mesh
          filename="$(find aero_description)/meshes/base_link.STL" />
      </geometry>
      <material
        name="">
        <color
          rgba="0.792156862745098 0.819607843137255 0.933333333333333 1" />
      </material>
    </visual>
    <collision>
      <origin
        xyz="0 0 0"
        rpy="0 0 0" />
      <geometry>
        <mesh
          filename="$(find aero_description)/meshes/base_link.STL" />
      </geometry>
    </collision>
  </link>
  

  <joint name="base_joint" type="fixed">
      <parent link="base_footprint" />
      <child link="base_link" />
      <origin xyz="0 0 ${base_height}" rpy="0 0 0" />
  </joint>


  <link
    name="link_rf">
    <inertial>
      <origin
        xyz="1.18406138227556E-08 0.0505304594240356 -4.11874865324791E-07"
        rpy="0 0 0" />
      <mass
        value="1.57217809961276" />
      <inertia
        ixx="0.00830966218082602"
        ixy="4.80752315071652E-09"
        ixz="-1.21598346886045E-08"
        iyy="0.015342723063461"
        iyz="-3.84664642974091E-09"
        izz="0.00830965872083907" />
    </inertial>
    <visual>
      <origin
        xyz="0 0 0"
        rpy="0 0 0" />
      <geometry>
        <mesh
          filename="$(find aero_description)/meshes/link_rf.STL" />
      </geometry>
      <material
        name="">
        <color
          rgba="0.752941176470588 0.752941176470588 0.752941176470588 1" />
      </material>
    </visual>
    <collision>
      <origin
        xyz="0 0 0"
        rpy="0 0 0" />
      <geometry>
        <mesh
          filename="$(find aero_description)/meshes/link_rf.STL" />
      </geometry>
    </collision>
  </link>
  <joint
    name="joint_rf"
    type="continuous">
    <origin
      xyz="0.407427184727014 -0.451926582248713 -0.326249999857664"
      rpy="0 0 0" />
    <parent
      link="base_link" />
    <child
      link="link_rf" />
    <axis
      xyz="0 1 0" />
  </joint>
  <link
    name="link_rb">
    <inertial>
      <origin
        xyz="-2.35175851459601E-07 0.0505304593987955 3.38276148925676E-07"
        rpy="0 0 0" />
      <mass
        value="1.57217810200607" />
      <inertia
        ixx="0.00830962071922625"
        ixy="-1.07236617117645E-08"
        ixz="-1.86089081692347E-08"
        iyy="0.0153426727742389"
        iyz="1.43549155640812E-08"
        izz="0.00830963926773048" />
    </inertial>
    <visual>
      <origin
        xyz="0 0 0"
        rpy="0 0 0" />
      <geometry>
        <mesh
          filename="$(find aero_description)/meshes/link_rb.STL" />
      </geometry>
      <material
        name="">
        <color
          rgba="0.752941176470588 0.752941176470588 0.752941176470588 1" />
      </material>
    </visual>
    <collision>
      <origin
        xyz="0 0 0"
        rpy="0 0 0" />
      <geometry>
        <mesh
          filename="$(find aero_description)/meshes/link_rb.STL" />
      </geometry>
    </collision>
  </link>
  <joint
    name="joint_rb"
    type="continuous">
    <origin
      xyz="-0.49745 -0.45193 -0.32641"
      rpy="0 0 0" />
    <parent
      link="base_link" />
    <child
      link="link_rb" />
    <axis
      xyz="0 1 0" />
  </joint>
  <link
    name="link_lf">
    <inertial>
      <origin
        xyz="-2.35149657079603E-07 -0.0505304593883816 -3.38317218268047E-07"
        rpy="0 0 0" />
      <mass
        value="1.57217810293052" />
      <inertia
        ixx="0.00830962015506777"
        ixy="1.07378923798342E-08"
        ixz="1.88337194259381E-08"
        iyy="0.0153426718764254"
        iyz="1.43590542699094E-08"
        izz="0.00830963896422886" />
    </inertial>
    <visual>
      <origin
        xyz="0 0 0"
        rpy="0 0 0" />
      <geometry>
        <mesh
          filename="$(find aero_description)/meshes/link_lf.STL" />
      </geometry>
      <material
        name="">
        <color
          rgba="0.752941176470588 0.752941176470588 0.752941176470588 1" />
      </material>
    </visual>
    <collision>
      <origin
        xyz="0 0 0"
        rpy="0 0 0" />
      <geometry>
        <mesh
          filename="$(find aero_description)/meshes/link_lf.STL" />
      </geometry>
    </collision>
  </link>
  <joint
    name="joint_lf"
    type="continuous">
    <origin
      xyz="0.40731 0.45067 -0.32641"
      rpy="0 0 0" />
    <parent
      link="base_link" />
    <child
      link="link_lf" />
    <axis
      xyz="0 1 0" />
  </joint>
  <link
    name="link_lb">
    <inertial>
      <origin
        xyz="-2.35123462921649E-07 -0.0505304593987954 -3.38358287721441E-07"
        rpy="0 0 0" />
      <mass
        value="1.57217810200607" />
      <inertia
        ixx="0.00830962063086315"
        ixy="1.07285262326192E-08"
        ixz="1.85737114193205E-08"
        iyy="0.0153426723439664"
        iyz="1.43489413057769E-08"
        izz="0.0083096389407193" />
    </inertial>
    <visual>
      <origin
        xyz="0 0 0"
        rpy="0 0 0" />
      <geometry>
        <mesh
          filename="$(find aero_description)/meshes/link_lb.STL" />
      </geometry>
      <material
        name="">
        <color
          rgba="0.752941176470588 0.752941176470588 0.752941176470588 1" />
      </material>
    </visual>
    <collision>
      <origin
        xyz="0 0 0"
        rpy="0 0 0" />
      <geometry>
        <mesh
          filename="$(find aero_description)/meshes/link_lb.STL" />
      </geometry>
    </collision>
  </link>
  <joint
    name="joint_lb"
    type="continuous">
    <origin
      xyz="-0.49757 0.45067 -0.32625"
      rpy="0 0 0" />
    <parent
      link="base_link" />
    <child
      link="link_lb" />
    <axis
      xyz="0 1 0" />
  </joint>




  <gazebo>
   <xacro:if value="$(arg is_ignition)">
      <plugin filename="ign_ros2_control-system" name="ign_ros2_control::IgnitionROS2ControlPlugin">
        <parameters>$(find rover_controller)/config/rover_controllers.yaml</parameters>
      </plugin>
      <plugin filename="ignition-gazebo-imu-system" name="ignition::gazebo::systems::Imu">
      </plugin>
    </xacro:if> 
  </gazebo>


</robot>